<?xml version="1.0"?>
<robot name="eyeexplorer_arm">

  <link name="base_link">
  </link>

  <joint name="joint0" type="fixed">
    <parent link="base_link"/>
    <child link="link1"/>
    <origin xyz="0.020 0 0" rpy="0 0 0" />
  </joint>

  <link name="link1">
  </link>

  <joint name="joint1" type="revolute">
    <parent link="link1"/>
    <child link="link2"/>
    <origin xyz="0 0 0.028" rpy="0 0 0" />
    <axis xyz="0 0 1" />
    <limit lower="-1.57" upper="1.57" effort="0.5293" velocity="6.159937255" />
    <friction friction="0.01" />
    <dynamics damping="0.4" />
  </joint>

  <link name="link2">
  </link>

  <joint name="joint2" type="revolute">
    <parent link="link2"/>
    <child link="link3"/>
    <origin xyz="0.2 0 0" rpy="0 0 0" />
    <axis xyz="0 1 0" />
    <limit lower="-1.57" upper="1.57" effort="0.5293" velocity="6.159937255" />
    <friction friction="0.01" />
    <dynamics damping="0.4" />
  </joint>


  <link name="link3">
  </link>

  <joint name="joint3" type="revolute">
    <parent link="link3"/>
    <child link="link4"/>
    <origin xyz="0 0 -0.2" rpy="0 0 0" />
    <axis xyz="0 1 0" />
    <limit lower="-1.046666667" upper="1.046666667" effort="0.5293" velocity="6.159937255" />>
    <friction friction="0.01" />
    <dynamics damping="0.4" />
  </joint>

 <link name="link4">
  </link>

  <joint name="offset_joint" type="revolute">
    <parent link="link4"/>
    <child link="gimbal_link5"/>
    <origin xyz="0.03982 0 -0.02239" rpy="0 0 0" />
    <axis xyz="0 1 0" />
    <limit lower="-1.57" upper="1.57" effort="0.5293" velocity="6.159937255" />
    <friction friction="0.01" />
    <dynamics damping="0.4" />
  </joint>

  <link name="gimbal_link5">
  </link>

  <joint name="gimbal_joint5" type="revolute">
    <parent link="gimbal_link5"/>
    <child link="gimbal_link6"/>
    <origin xyz="0 0 0.4" rpy="0 0.785398163 0" />
    <axis xyz="0.707106781 0 0.707106781" />
    <limit lower="-1.046666667" upper="1.046666667" effort="0.5293" velocity="6.159937255" />
    <friction friction="0.01" />
    <dynamics damping="0.4" />
  </joint>

  <link name="gimbal_link6">
  </link>

  <joint name="gimbal_joint6" type="revolute">
    <parent link="gimbal_link6"/>
    <child link="endoscope_link"/>
    <origin xyz="0 0 0" rpy="0 0 0" />
    <axis xyz="0.707106781 0 -0.707106781" />
    <limit lower="-1.046666667" upper="1.046666667" effort="0.5293" velocity="6.159937255" />
    <dynamics damping="0.4" />
  </joint>


 <link name="endoscope_link">
  </link>

  <joint name="endoscope_joint" type="revolute">
    <parent link="endoscope_link"/>
    <child link="endoscope_tip"/>
    <origin xyz="0.1 0 0" rpy="0 0.785398163 0" />
    <axis xyz="0.707106781 0 -0.707106781" />
    <limit lower="-1.046666667" upper="1.046666667" effort="0.5293" velocity="6.159937255" />
  </joint>

   <link name="endoscope_tip">
  </link>

</robot>