<?xml version="1.0" ?>
<robot name="eyeexplorer3">
  <!-- Import your models -->
  <material name="ARM/black">
    <color rgba="0.0 0.0 0.0 1.0"/>
  </material>
  <material name="ARM/blue">
    <color rgba="0.0 0.0 0.8 1.0"/>
  </material>
  <material name="ARM/green">
    <color rgba="0.0 0.8 0.0 1.0"/>
  </material>
  <material name="ARM/grey">
    <color rgba="0.2 0.2 0.2 1.0"/>
  </material>
  <material name="ARM/orange">
    <color rgba="1.0 0.423529411765 0.0392156862745 1.0"/>
  </material>
  <material name="ARM/brown">
    <color rgba="0.870588235294 0.811764705882 0.764705882353 1.0"/>
  </material>
  <material name="ARM/red">
    <color rgba="0.8 0.0 0.0 1.0"/>
  </material>
  <material name="ARM/white">
    <color rgba="1.0 1.0 1.0 1.0"/>
  </material>

  <!-- Build your comprehensive robot -->
  <link name="world"/>

  <joint name="arm_joint1" type="continuous">
    <parent link="world"/>
    <child link="link_base"/>
    <origin rpy="0 0 0" xyz="0.0 0 0.0"/>
    <axis xyz="0 0 1"/>
  </joint>

  <link name="link_base">
    <visual>
      <geometry>
        <box size = "0.009 0.01 0.032"/>
      </geometry>
      <origin rpy="0 0 0" xyz="0.0045 0 0.016"/>
      <material name="ARM/orange"/>
    </visual>
  </link>

  <joint name="arm_joint2" type="continuous">
    <parent link="link_base"/>
    <child link="arm_link1"/>
    <origin rpy="0 0 0" xyz="0.009 0 0.032"/>
    <axis xyz="0 1 0"/>
  </joint>

  <link name="arm_link1">
    <visual>
      <geometry>
        <box size = "0.2 0.03 0.03"/>
      </geometry>
      <origin rpy="0 0 0" xyz="0.1 0 0"/>
      <material name="ARM/orange"/>
    </visual>
  </link>

  <joint name="arm_joint_horiz1" type="continuous">
    <parent link="arm_link1"/>
    <child link="arm_link_para1"/>
    <origin rpy="0 0 0" xyz="0.2 0 0"/>
    <axis xyz="0 1 0"/>
  </joint>

  <link name="arm_link_para1">
    <visual>
      <geometry>
        <box size="0.03232 0.03 0.01768"/>
      </geometry>
      <origin rpy="0 0 0" xyz="0.01616 0 0.00884"/>
      <material name="ARM/orange"/>
    </visual>
  </link>

  <joint name="arm_joint3" type="continuous">
    <parent link="arm_link_para1"/>
    <child link="arm_link2"/>
    <origin rpy="0 0 0" xyz="0.03232 0 0.01768"/>
    <axis xyz="0 1 0"/>
  </joint>

  <link name="arm_link2">
    <visual>
      <geometry>
        <box size="0.03 0.03 -0.2"/>
      </geometry>
      <origin rpy="0 0 0" xyz="0 0 -0.1"/>
      <material name="ARM/orange"/>
    </visual>
  </link>

  <joint name="arm_joint_horiz2" type="continuous">
    <parent link="arm_link2"/>
    <child link="arm_link_para2"/>
    <origin rpy="0 0 0" xyz="0 0 -0.2"/>
    <axis xyz="0 1 0"/>
  </joint>

  <link name="arm_link_para2">
    <visual>
      <geometry>
        <box size="0.054 0.02 -0.019"/>
      </geometry>
      <origin rpy="0 0 0" xyz="0.027 0.0 -0.0095"/>
      <material name="ARM/orange"/>
    </visual>
  </link>

  <joint name="arm_joint4" type="continuous">
    <parent link="arm_link_para2"/>
    <child link="arm_link50"/>
    <origin rpy="0 0 0" xyz="0.054 0.0005 -0.019"/>
    <axis xyz="1 0 0"/>
  </joint>

  <link name="arm_link50">
    <visual>
      <geometry>
        <box size="0.02 -0.06 0.02"/>
      </geometry>
      <origin rpy="0 0 0" xyz="0 -0.03 0"/>
      <material name="ARM/red"/>
    </visual>
  </link>

  <joint name="arm_joint_gimbal" type="fixed">
    <parent link="arm_link50"/>
    <child link="arm_link51"/>
    <origin rpy="0 0 0" xyz="0 -0.06 0"/>
  </joint>

  <link name="arm_link51">
    <visual>
      <geometry>
        <box size="0.1074 0.02 0.02"/>
      </geometry>
      <origin rpy="0 0 0" xyz="0.0537 0 0"/>
      <material name="ARM/red"/>
    </visual>
  </link>

  <joint name="arm_joint5" type="continuous">
    <parent link="arm_link51"/>
    <child link="arm_link6"/>
    <origin rpy="0 0 0" xyz="0.1074 0 0"/>
    <axis xyz="0 1 0"/>
  </joint>

  <link name="arm_link6">
    <visual>
      <geometry>
        <box size="0.02 0.06 0.02"/>
      </geometry>
      <origin rpy="0 0 0" xyz="0 0.03 0"/>
      <material name="ARM/red"/>
    </visual>
  </link>

  <joint name="endoscope_holder" type="fixed">
    <parent link="arm_link6"/>
    <child link="endoscope_holder_link"/>
    <origin rpy="0 0 0" xyz="0 0.06 0"/>
  </joint>

  <link name="endoscope_holder_link">
    <visual>
      <geometry>
        <box size="0.02 0.02 -0.03"/>
      </geometry>
      <origin rpy="0 0 0" xyz="0 0 -0.015"/>
      <material name="ARM/red"/>
    </visual>
  </link>

  <joint name="endoscope_joint" type="fixed">
    <parent link="endoscope_holder_link"/>
    <child link="endoscope_link"/>
    <origin rpy="0 0 0" xyz="0 0 -0.03"/>
  </joint>

  <link name="endoscope_link">
    <visual>
      <geometry>
        <box size="0.01 0.01 -0.03"/>
      </geometry>
      <origin rpy="0 0 0" xyz="0 0 -0.015"/>
      <material name="ARM/black"/>
    </visual>
  </link>

  <joint name="endoscope_joint_deflect1" type="fixed">
    <parent link="endoscope_link"/>
    <child link="endoscope_link_dif1"/>
    <origin rpy="0 0 0.966345" xyz="0 0 -0.03"/>
  </joint>

  <link name="endoscope_link_dif1">
    <visual>
      <geometry>
        <box size="0.002 0.002 -0.03"/>
      </geometry>
      <origin rpy="0 0 0" xyz="0 0 -0.015"/>
      <material name="ARM/white"/>
    </visual>
  </link>

  <joint name="endoscope_camera_dif" type="fixed">
    <parent link="endoscope_link_dif1"/>
    <child link="endoscope_org1"/>
    <origin rpy="-0.02899 0 0" xyz="0 0.005179 -0.03"/>
  </joint>

  <link name="endoscope_org1">
    <visual>
      <geometry>
        <box size="0 0 0"/>
      </geometry>
      <origin rpy="0 0 0" xyz="0 0 0"/>
      <material name="ARM/white"/>
    </visual>
  </link>

  <joint name="endoscope_camera_dif2" type="fixed">
    <parent link="endoscope_org1"/>
    <child link="endoscope_org2"/>
    <origin rpy="0 0 -0.966345" xyz="0 0 0"/>
  </joint>

  <link name="endoscope_org2">
    <visual>
      <geometry>
        <box size="0 0 0"/>
      </geometry>
      <origin rpy="0 0 0" xyz="0 0 0"/>
      <material name="ARM/white"/>
    </visual>
  </link>

  <joint name="endoscope_camera" type="fixed">
    <parent link="endoscope_org2"/>
    <child link="endoscope"/>
    <origin rpy="0 3.14 0" xyz="0 0 0"/>
  </joint>

  <link name="endoscope">
    <visual>
      <geometry>
        <box size="0 0 0"/>
      </geometry>
      <origin rpy="0 0 0" xyz="0 0 0"/>
      <material name="ARM/white"/>
    </visual>
  </link>
</robot>

